<?xml version="1.0" ?>
<sdf version="1.9">

  <!-- Main frame of the model-->
  <model name="dropper_drone">
    <pose>0 0 0 0 0 0</pose>
    <link name="base_link">

      <sensor name="imu_sensor" type="imu">
        <always_on>1</always_on>
        <update_rate>1000</update_rate>
      </sensor>

      <inertial>
        <mass>1.410</mass>
        <pose>-0.002060 -0.001083 0.034620 0 0 0</pose>
        <inertia>
          <ixx>0.0034</ixx>
          <iyy>0.0043</iyy>
          <izz>0.0055</izz>
          <ixy>0.0</ixy>
          <ixz>0.0</ixz>
          <iyz>0.0</iyz>
        </inertia>
      </inertial>
      
      <visual name="base_link_visual">
        <pose>0 0 0 0 0 0</pose>
        <geometry>
          <mesh><uri>../01_mechanics/CAD/Drone_assembly_gazebo.obj</uri></mesh>
        </geometry>
      </visual>
      
      <collision name="bottom_plate_collision">
        <pose>0.0 0.0 0.01 0 0 0</pose>
        <geometry>
          <box>
            <size>0.185 0.185 0.02</size>
          </box>
        </geometry>
        <surface>
          <contact>
            <ode>
              <max_vel>100.0</max_vel>
              <min_depth>0.001</min_depth>
            </ode>
          </contact>
          <friction>
            <ode>
              <mu>100.0</mu>
              <mu2>100.0</mu2>
            </ode>
          </friction>
        </surface>
      </collision>
      <collision name="electronics_compartment_collision">
        <pose>0 0 0.017 0 0 0</pose>
        <geometry>
          <box>
            <size>0.12 0.055 0.024</size>
          </box>
        </geometry>
        <surface>
          <contact>
            <ode>
              <max_vel>100.0</max_vel>
              <min_depth>0.001</min_depth>
            </ode>
          </contact>
          <friction>
            <ode>
              <mu>100.0</mu>
              <mu2>100.0</mu2>
            </ode>
          </friction>
        </surface>
      </collision>
      <collision name="battery_collision">
        <pose>0 0 0.048 0 0 0</pose>
        <geometry>
          <box>
            <size>0.078 0.038 0.038</size>
          </box>
        </geometry>
        <surface>
          <contact>
            <ode>
              <max_vel>100.0</max_vel>
              <min_depth>0.001</min_depth>
            </ode>
          </contact>
          <friction>
            <ode>
              <mu>100.0</mu>
              <mu2>100.0</mu2>
            </ode>
          </friction>
        </surface>
      </collision>
      <collision name="motor0_collision">
        <pose>0.088388 -0.088388 0.0137065 0 0 0</pose>
        <geometry>
          <cylinder>
            <radius>0.027</radius>
            <length>0.017</length>
          </cylinder>
        </geometry>
        <surface>
          <contact>
            <ode>
              <max_vel>100.0</max_vel>
              <min_depth>0.001</min_depth>
            </ode>
          </contact>
          <friction>
            <ode>
              <mu>100.0</mu>
              <mu2>100.0</mu2>
            </ode>
          </friction>
        </surface>
      </collision>
      <collision name="motor1_collision">
        <pose>-0.088388 0.088388 0.0137065 0 0 0</pose>
        <geometry>
          <cylinder>
            <radius>0.027</radius>
            <length>0.017</length>
          </cylinder>
        </geometry>
        <surface>
          <contact>
            <ode>
              <max_vel>100.0</max_vel>
              <min_depth>0.001</min_depth>
            </ode>
          </contact>
          <friction>
            <ode>
              <mu>100.0</mu>
              <mu2>100.0</mu2>
            </ode>
          </friction>
        </surface>
      </collision>
      <collision name="motor2_collision">
        <pose>0.088388 0.088388 0.0137065 0 0 0</pose>
        <geometry>
          <cylinder>
            <radius>0.027</radius>
            <length>0.017</length>
          </cylinder>
        </geometry>
        <surface>
          <contact>
            <ode>
              <max_vel>100.0</max_vel>
              <min_depth>0.001</min_depth>
            </ode>
          </contact>
          <friction>
            <ode>
              <mu>100.0</mu>
              <mu2>100.0</mu2>
            </ode>
          </friction>
        </surface>
      </collision>
      <collision name="motor3_collision">
        <pose>-0.088388 -0.088388 0.0137065 0 0 0</pose>
        <geometry>
          <cylinder>
            <radius>0.027</radius>
            <length>0.017</length>
          </cylinder>
        </geometry>
        <surface>
          <contact>
            <ode>
              <max_vel>100.0</max_vel>
              <min_depth>0.001</min_depth>
            </ode>
          </contact>
          <friction>
            <ode>
              <mu>100.0</mu>
              <mu2>100.0</mu2>
            </ode>
          </friction>
        </surface>
      </collision>

    </link>

    <link name="rotor_0">
      <pose>0.088388 -0.088388 0.022715 0 0 0</pose> 
      <inertial>
        <mass>0.023</mass>
        <pose>0 0 0 0 0 0</pose>
        <inertia><ixx>0.000008</ixx><iyy>0.000008</iyy><izz>0.000015</izz><ixy>0</ixy><ixz>0</ixz><iyz>0</iyz></inertia>
      </inertial>
      <visual name="rotor_0_visual">
        <geometry><mesh><uri>../01_mechanics/CAD/CCW_propeller.obj</uri></mesh></geometry>
      </visual>
    </link>
    <joint name="rotor_0_joint" type="revolute">
      <parent>base_link</parent>
      <child>rotor_0</child>
      <axis>
        <xyz>0 0 1</xyz>
        <limit><lower>-1e+16</lower><upper>1e+16</upper></limit>
        <dynamics><damping>0.0002</damping><friction>0.0002</friction></dynamics>
      </axis>
    </joint>

    <link name="rotor_1">
      <pose>-0.088388 0.088388 0.022715 0 0 0</pose> 
      <inertial>
        <mass>0.023</mass>
        <pose>0 0 0 0 0 0</pose>
        <inertia><ixx>0.000008</ixx><iyy>0.000008</iyy><izz>0.000015</izz><ixy>0</ixy><ixz>0</ixz><iyz>0</iyz></inertia>
      </inertial>
      <visual name="rotor_1_visual">
        <geometry><mesh><uri>../01_mechanics/CAD/CCW_propeller.obj</uri></mesh></geometry>
      </visual>
    </link>
    <joint name="rotor_1_joint" type="revolute">
      <parent>base_link</parent>
      <child>rotor_1</child>
      <axis>
        <xyz>0 0 1</xyz> 
        <limit><lower>-1e+16</lower><upper>1e+16</upper></limit>
        <dynamics><damping>0.0002</damping><friction>0.0002</friction></dynamics>
      </axis>
    </joint>

    <link name="rotor_2">
      <pose>0.088388 0.088388 0.022715 0 0 0</pose> 
      <inertial>
        <mass>0.023</mass>
        <pose>0 0 0 0 0 0</pose>
        <inertia><ixx>0.000008</ixx><iyy>0.000008</iyy><izz>0.000015</izz><ixy>0</ixy><ixz>0</ixz><iyz>0</iyz></inertia>
      </inertial>
      <visual name="rotor_2_visual">
        <geometry><mesh><uri>../01_mechanics/CAD/CW_propeller.obj</uri></mesh></geometry>
      </visual>
    </link>
    <joint name="rotor_2_joint" type="revolute">
      <parent>base_link</parent>
      <child>rotor_2</child>
      <axis>
        <xyz>0 0 1</xyz>
        <limit><lower>-1e+16</lower><upper>1e+16</upper></limit>
        <dynamics><damping>0.0002</damping><friction>0.0002</friction></dynamics>
      </axis>
    </joint>
    
    <link name="rotor_3">
      <pose>-0.088388 -0.088388 0.022715 0 0 0</pose> 
      <inertial>
        <mass>0.023</mass>
        <pose>0 0 0 0 0 0</pose>
        <inertia><ixx>0.000008</ixx><iyy>0.000008</iyy><izz>0.000015</izz><ixy>0</ixy><ixz>0</ixz><iyz>0</iyz></inertia>
      </inertial>
      <visual name="rotor_3_visual">
        <geometry><mesh><uri>../01_mechanics/CAD/CW_propeller.obj</uri></mesh></geometry>
      </visual>
    </link>
    <joint name="rotor_3_joint" type="revolute">
      <parent>base_link</parent>
      <child>rotor_3</child>
      <axis>
        <xyz>0 0 1</xyz>
        <limit><lower>-1e+16</lower><upper>1e+16</upper></limit>
        <dynamics><damping>0.0002</damping><friction>0.0002</friction></dynamics>
      </axis>
    </joint>

    <model name="payload_model">
      <link name="payload_link">
        <pose>0 0 -0.06 0 0 0</pose>
        <inertial>
          <mass>0.5</mass>
          <pose>0 0 0 0 0 0</pose>
          <inertia>
            <ixx>0.000208</ixx>
            <ixy>0</ixy>
            <ixz>0</ixz>
            <iyy>0.000208</iyy>
            <iyz>0</iyz>
            <izz>0.000208</izz>
          </inertia>
        </inertial>
        <visual name="payload_visual">
          <geometry>
            <box>
              <size>0.05 0.05 0.05</size>
            </box>
          </geometry>
          <material>
            <ambient>1.00 0.35 0.00 1.0</ambient>
            <diffuse>1.00 0.35 0.00 1.0</diffuse>
          </material>
        </visual>
        <collision name="payload_collision">
          <geometry>
            <box>
              <size>0.05 0.05 0.05</size>
            </box>
          </geometry>
        </collision>
      </link>
    </model>

    <plugin filename="gz-sim-detachable-joint-system" name="gz::sim::systems::DetachableJoint">
      <parent_link>base_link</parent_link>
      <child_model>payload_model</child_model>
      <child_link>payload_link</child_link>
      <detach_topic>/payload/detach</detach_topic>
    </plugin>
    
    <plugin filename="gz-sim-joint-state-publisher-system" name="gz::sim::systems::JointStatePublisher"></plugin>

    <plugin filename="gz-sim-lift-drag-system" name="gz::sim::systems::LiftDrag">
      <a0>0.35</a0>
      <alpha_stall>1.5</alpha_stall>
      <cla>1.03</cla>
      <cda>0.025</cda>
      <cma>0.0</cma>
      <cla_stall>-0.1</cla_stall>
      <cda_stall>0.15</cda_stall>
      <cma_stall>0.0</cma_stall>
      <area>0.0008</area>
      <air_density>1.2041</air_density>
      <cp>0.045 0 0</cp>
      <forward>0 1 0</forward> 
      <upward>0 0 1</upward>
      <link_name>rotor_0</link_name>
    </plugin>
    <plugin filename="gz-sim-lift-drag-system" name="gz::sim::systems::LiftDrag">
     <a0>0.35</a0>
      <alpha_stall>1.5</alpha_stall>
      <cla>1.03</cla>
      <cda>0.025</cda>
      <cma>0.0</cma>
      <cla_stall>-0.1</cla_stall>
      <cda_stall>0.15</cda_stall>
      <cma_stall>0.0</cma_stall>
      <area>0.0008</area>
      <air_density>1.2041</air_density>
      <cp>-0.045 0 0</cp>
      <forward>0 -1 0</forward> 
      <upward>0 0 1</upward>
      <link_name>rotor_0</link_name>
    </plugin>

    <plugin filename="gz-sim-lift-drag-system" name="gz::sim::systems::LiftDrag">
      <a0>0.35</a0>
      <alpha_stall>1.5</alpha_stall>
      <cla>1.03</cla>
      <cda>0.025</cda>
      <cma>0.0</cma>
      <cla_stall>-0.1</cla_stall>
      <cda_stall>0.15</cda_stall>
      <cma_stall>0.0</cma_stall>
      <area>0.0008</area>
      <air_density>1.2041</air_density>
      <cp>0.045 0 0</cp>
      <forward>0 1 0</forward> 
      <upward>0 0 1</upward>
      <link_name>rotor_1</link_name>
    </plugin>
    <plugin filename="gz-sim-lift-drag-system" name="gz::sim::systems::LiftDrag">
      <a0>0.35</a0>
      <alpha_stall>1.5</alpha_stall>
      <cla>1.03</cla>
      <cda>0.025</cda>
      <cma>0.0</cma>
      <cla_stall>-0.1</cla_stall>
      <cda_stall>0.15</cda_stall>
      <cma_stall>0.0</cma_stall>
      <area>0.0008</area>
      <air_density>1.2041</air_density>
      <cp>-0.045 0 0</cp>
      <forward>0 -1 0</forward> 
      <upward>0 0 1</upward>
      <link_name>rotor_1</link_name>
    </plugin>

    <plugin filename="gz-sim-lift-drag-system" name="gz::sim::systems::LiftDrag">
      <a0>0.35</a0>
      <alpha_stall>1.5</alpha_stall>
      <cla>1.03</cla>
      <cda>0.025</cda>
      <cma>0.0</cma>
      <cla_stall>-0.1</cla_stall>
      <cda_stall>0.15</cda_stall>
      <cma_stall>0.0</cma_stall>
      <area>0.0008</area>
      <air_density>1.2041</air_density>
      <cp>0.045 0 0</cp>
      <forward>0 -1 0</forward> 
      <upward>0 0 1</upward>
      <link_name>rotor_2</link_name>
    </plugin>
    <plugin filename="gz-sim-lift-drag-system" name="gz::sim::systems::LiftDrag">
      <a0>0.35</a0>
      <alpha_stall>1.5</alpha_stall>
      <cla>1.03</cla>
      <cda>0.025</cda>
      <cma>0.0</cma>
      <cla_stall>-0.1</cla_stall>
      <cda_stall>0.15</cda_stall>
      <cma_stall>0.0</cma_stall>
      <area>0.0008</area>
      <air_density>1.2041</air_density>
      <cp>-0.045 0 0</cp>
      <forward>0 1 0</forward>
      <upward>0 0 1</upward>
      <link_name>rotor_2</link_name>
    </plugin>

    <plugin filename="gz-sim-lift-drag-system" name="gz::sim::systems::LiftDrag">
      <a0>0.35</a0>
      <alpha_stall>1.5</alpha_stall>
      <cla>1.03</cla>
      <cda>0.025</cda>
      <cma>0.0</cma>
      <cla_stall>-0.1</cla_stall>
      <cda_stall>0.15</cda_stall>
      <cma_stall>0.0</cma_stall>
      <area>0.0008</area>
      <air_density>1.2041</air_density>
      <cp>0.045 0 0</cp>
      <forward>0 -1 0</forward> 
      <upward>0 0 1</upward>
      <link_name>rotor_3</link_name>
    </plugin>
    <plugin filename="gz-sim-lift-drag-system" name="gz::sim::systems::LiftDrag">
      <a0>0.35</a0>
      <alpha_stall>1.5</alpha_stall>
      <cla>1.03</cla>
      <cda>0.025</cda>
      <cma>0.0</cma>
      <cla_stall>-0.1</cla_stall>
      <cda_stall>0.15</cda_stall>
      <cma_stall>0.0</cma_stall>
      <area>0.0008</area>
      <air_density>1.2041</air_density>
      <cp>-0.045 0 0</cp>
      <forward>0 1 0</forward> 
      <upward>0 0 1</upward>
      <link_name>rotor_3</link_name>
    </plugin>

    <plugin filename="gz-sim-apply-joint-force-system" name="gz::sim::systems::ApplyJointForce"><joint_name>rotor_0_joint</joint_name></plugin>
    <plugin filename="gz-sim-apply-joint-force-system" name="gz::sim::systems::ApplyJointForce"><joint_name>rotor_1_joint</joint_name></plugin>
    <plugin filename="gz-sim-apply-joint-force-system" name="gz::sim::systems::ApplyJointForce"><joint_name>rotor_2_joint</joint_name></plugin>
    <plugin filename="gz-sim-apply-joint-force-system" name="gz::sim::systems::ApplyJointForce"><joint_name>rotor_3_joint</joint_name></plugin>

    <plugin filename="ArduPilotPlugin" name="ArduPilotPlugin">
      <fdm_addr>127.0.0.1</fdm_addr>
      <fdm_port_in>9002</fdm_port_in>
      <connectionTimeoutMaxCount>5</connectionTimeoutMaxCount>
      <lock_step>1</lock_step>
      <no_time_sync>1</no_time_sync>
      <have_32_channels>0</have_32_channels>
      
      <modelXYZToAirplaneXForwardZDown>0 0 0 3.14159 0 0</modelXYZToAirplaneXForwardZDown>
      <gazeboXYZToNED>0 0 0 3.14159 0 0</gazeboXYZToNED>
      <modelName>dropper_drone</modelName>
      <imuName>imu_sensor</imuName>
      
      <control channel="0">
        <jointName>rotor_0_joint</jointName>
        <useForce>1</useForce>
        <multiplier>3665</multiplier>
        <offset>0</offset>
        <servo_min>1000</servo_min>
        <servo_max>2000</servo_max>
        <type>VELOCITY</type>
        <p_gain>0.1</p_gain><i_gain>0</i_gain><d_gain>0</d_gain>
        <cmd_max>2.5</cmd_max>
        <cmd_min>-2.5</cmd_min>
        <controlVelocitySlowdownSim>1</controlVelocitySlowdownSim>
      </control>

      <control channel="1">
        <jointName>rotor_1_joint</jointName>
        <useForce>1</useForce>
        <multiplier>3665</multiplier>
        <offset>0</offset>
        <servo_min>1000</servo_min>
        <servo_max>2000</servo_max>
        <type>VELOCITY</type>
        <p_gain>0.1</p_gain><i_gain>0</i_gain><d_gain>0</d_gain>
        <cmd_max>2.5</cmd_max>
        <cmd_min>-2.5</cmd_min>
        <controlVelocitySlowdownSim>1</controlVelocitySlowdownSim>
      </control>

      <control channel="2">
        <jointName>rotor_2_joint</jointName>
        <useForce>1</useForce>
        <multiplier>-3665</multiplier>
        <offset>0</offset>
        <servo_min>1000</servo_min>
        <servo_max>2000</servo_max>
        <type>VELOCITY</type>
        <p_gain>0.1</p_gain><i_gain>0</i_gain><d_gain>0</d_gain>
        <cmd_max>2.5</cmd_max>
        <cmd_min>-2.5</cmd_min>
        <controlVelocitySlowdownSim>1</controlVelocitySlowdownSim>
      </control>

      <control channel="3">
        <jointName>rotor_3_joint</jointName>
        <useForce>1</useForce>
        <multiplier>-3665</multiplier>
        <offset>0</offset>
        <servo_min>1000</servo_min>
        <servo_max>2000</servo_max>
        <type>VELOCITY</type>
        <p_gain>0.1</p_gain><i_gain>0</i_gain><d_gain>0</d_gain>
        <cmd_max>2.5</cmd_max>
        <cmd_min>-2.5</cmd_min>
        <controlVelocitySlowdownSim>1</controlVelocitySlowdownSim>
      </control>

    </plugin>
  </model>
</sdf>